<?xml version="1.0" ?>
<!-- =================================================================================== -->
<!-- |    This document was autogenerated by xacro from urdf\Final.xacro               | -->
<!-- |    EDITING THIS FILE BY HAND IS NOT RECOMMENDED                                 | -->
<!-- =================================================================================== -->
<robot xmlns:xacro="http://www.ros.org/wiki/xacro" name="Final">
  <material name="silver">
    <color rgba="0.700 0.700 0.700 1.000"/>
  </material>
  <transmission name="Slider 1_tran">
    <type>transmission_interface/SimpleTransmission</type>
    <joint name="Slider 1">
      <hardwareInterface>hardware_interface/EffortJointInterface</hardwareInterface>
    </joint>
    <actuator name="Slider 1_actr">
      <hardwareInterface>hardware_interface/EffortJointInterface</hardwareInterface>
      <mechanicalReduction>1</mechanicalReduction>
    </actuator>
  </transmission>
  <transmission name="Slider 4_tran">
    <type>transmission_interface/SimpleTransmission</type>
    <joint name="Slider 4">
      <hardwareInterface>hardware_interface/EffortJointInterface</hardwareInterface>
    </joint>
    <actuator name="Slider 4_actr">
      <hardwareInterface>hardware_interface/EffortJointInterface</hardwareInterface>
      <mechanicalReduction>1</mechanicalReduction>
    </actuator>
  </transmission>
  <transmission name="Slider 5_tran">
    <type>transmission_interface/SimpleTransmission</type>
    <joint name="Slider 5">
      <hardwareInterface>hardware_interface/EffortJointInterface</hardwareInterface>
    </joint>
    <actuator name="Slider 5_actr">
      <hardwareInterface>hardware_interface/EffortJointInterface</hardwareInterface>
      <mechanicalReduction>1</mechanicalReduction>
    </actuator>
  </transmission>
  <gazebo>
    <plugin name="control" filename="libgazebo_ros_control.so"/>
  </gazebo>
  <gazebo reference="base_link">
    <material>Gazebo/Silver</material>
    <mu1>0.2</mu1>
    <mu2>0.2</mu2>
    <selfCollide>true</selfCollide>
    <gravity>true</gravity>
  </gazebo>
  <gazebo reference="down_1">
    <material>Gazebo/Silver</material>
    <mu1>0.2</mu1>
    <mu2>0.2</mu2>
    <selfCollide>true</selfCollide>
  </gazebo>
  <gazebo reference="UP2_1">
    <material>Gazebo/Silver</material>
    <mu1>0.2</mu1>
    <mu2>0.2</mu2>
    <selfCollide>true</selfCollide>
  </gazebo>
  <gazebo reference="UP1_1">
    <material>Gazebo/Silver</material>
    <mu1>0.2</mu1>
    <mu2>0.2</mu2>
    <selfCollide>true</selfCollide>
  </gazebo>
  <gazebo reference="down1_1">
    <material>Gazebo/Silver</material>
    <mu1>0.2</mu1>
    <mu2>0.2</mu2>
    <selfCollide>true</selfCollide>
  </gazebo>
  <gazebo reference="down2_1">
    <material>Gazebo/Silver</material>
    <mu1>0.2</mu1>
    <mu2>0.2</mu2>
    <selfCollide>true</selfCollide>
  </gazebo>
  <link name="base_link">
    <inertial>
      <origin xyz="2.165463575649829e-17 0.0 0.006428571428571429" rpy="0 0 0"/>
      <mass value="3.297"/>
      <inertia ixx="0.003651" iyy="0.024795" izz="0.028311" ixy="-0.0" iyz="0.0" ixz="0.0"/>
    </inertial>
    <visual>
      <origin xyz="0 0 0" rpy="0 0 0"/>
      <geometry>
        <mesh filename="package://Final_description/meshes/base_link.stl" scale="0.001 0.001 0.001"/>
      </geometry>
      <material name="silver"/>
    </visual>
    <collision>
      <origin xyz="0 0 0" rpy="0 0 0"/>
      <geometry>
        <mesh filename="package://Final_description/meshes/base_link.stl" scale="0.001 0.001 0.001"/>
      </geometry>
    </collision>
  </link>
  <link name="down_1">
    <inertial>
      <origin xyz="0.0 0.02 0.0006250000000000006" rpy="0 0 0"/>
      <mass value="0.37679999999999997"/>
      <inertia ixx="0.000388" iyy="0.000118" izz="0.000495" ixy="-0.0" iyz="0.0" ixz="0.0"/>
    </inertial>
    <visual>
      <origin xyz="0.0 0.02 -0.02" rpy="0 0 0"/>
      <geometry>
        <mesh filename="package://Final_description/meshes/down_1.stl" scale="0.001 0.001 0.001"/>
      </geometry>
      <material name="silver"/>
    </visual>
    <collision>
      <origin xyz="0.0 0.02 -0.02" rpy="0 0 0"/>
      <geometry>
        <mesh filename="package://Final_description/meshes/down_1.stl" scale="0.001 0.001 0.001"/>
      </geometry>
    </collision>
  </link>
  <link name="UP2_1">
    <inertial>
      <origin xyz="2.165463575649829e-17 0.06 0.0014285714285714292" rpy="0 0 0"/>
      <mass value="3.297"/>
      <inertia ixx="0.003651" iyy="0.024795" izz="0.028311" ixy="-0.0" iyz="0.0" ixz="0.0"/>
    </inertial>
    <visual>
      <origin xyz="-0.0 -0.06 -0.005" rpy="0 0 0"/>
      <geometry>
        <mesh filename="package://Final_description/meshes/UP2_1.stl" scale="0.001 0.001 0.001"/>
      </geometry>
      <material name="silver"/>
    </visual>
    <collision>
      <origin xyz="-0.0 -0.06 -0.005" rpy="0 0 0"/>
      <geometry>
        <mesh filename="package://Final_description/meshes/UP2_1.stl" scale="0.001 0.001 0.001"/>
      </geometry>
    </collision>
  </link>
  <link name="UP1_1">
    <inertial>
      <origin xyz="2.165463575649829e-17 -0.06 0.0014285714285714292" rpy="0 0 0"/>
      <mass value="3.297"/>
      <inertia ixx="0.003651" iyy="0.024795" izz="0.028311" ixy="-0.0" iyz="0.0" ixz="0.0"/>
    </inertial>
    <visual>
      <origin xyz="-0.0 0.06 -0.005" rpy="0 0 0"/>
      <geometry>
        <mesh filename="package://Final_description/meshes/UP1_1.stl" scale="0.001 0.001 0.001"/>
      </geometry>
      <material name="silver"/>
    </visual>
    <collision>
      <origin xyz="-0.0 0.06 -0.005" rpy="0 0 0"/>
      <geometry>
        <mesh filename="package://Final_description/meshes/UP1_1.stl" scale="0.001 0.001 0.001"/>
      </geometry>
    </collision>
  </link>
  <link name="down1_1">
    <inertial>
      <origin xyz="0.0 0.01999999999999999 0.0006249999999999936" rpy="0 0 0"/>
      <mass value="0.37679999999999997"/>
      <inertia ixx="0.000388" iyy="0.000118" izz="0.000495" ixy="-0.0" iyz="0.0" ixz="0.0"/>
    </inertial>
    <visual>
      <origin xyz="0.0 -0.1 -0.02" rpy="0 0 0"/>
      <geometry>
        <mesh filename="package://Final_description/meshes/down1_1.stl" scale="0.001 0.001 0.001"/>
      </geometry>
      <material name="silver"/>
    </visual>
    <collision>
      <origin xyz="0.0 -0.1 -0.02" rpy="0 0 0"/>
      <geometry>
        <mesh filename="package://Final_description/meshes/down1_1.stl" scale="0.001 0.001 0.001"/>
      </geometry>
    </collision>
  </link>
  <link name="down2_1">
    <inertial>
      <origin xyz="0.0 0.020000000000000018 0.0006250000000000006" rpy="0 0 0"/>
      <mass value="0.37679999999999997"/>
      <inertia ixx="0.000388" iyy="0.000118" izz="0.000495" ixy="-0.0" iyz="-0.0" ixz="0.0"/>
    </inertial>
    <visual>
      <origin xyz="0.0 0.14 -0.02" rpy="0 0 0"/>
      <geometry>
        <mesh filename="package://Final_description/meshes/down2_1.stl" scale="0.001 0.001 0.001"/>
      </geometry>
      <material name="silver"/>
    </visual>
    <collision>
      <origin xyz="0.0 0.14 -0.02" rpy="0 0 0"/>
      <geometry>
        <mesh filename="package://Final_description/meshes/down2_1.stl" scale="0.001 0.001 0.001"/>
      </geometry>
    </collision>
  </link>
  <joint name="Slider 1" type="prismatic">
    <origin xyz="0.0 -0.02 0.02" rpy="0 0 0"/>
    <parent link="base_link"/>
    <child link="down_1"/>
    <axis xyz="1.0 0.0 0.0"/>
    <limit upper="0.12" lower="-0.12" effort="100" velocity="100"/>
  </joint>
  <joint name="Rigid 2" type="fixed">
    <origin xyz="0.0 0.06 0.005" rpy="0 0 0"/>
    <parent link="base_link"/>
    <child link="UP2_1"/>
  </joint>
  <joint name="Rigid 3" type="fixed">
    <origin xyz="0.0 -0.06 0.005" rpy="0 0 0"/>
    <parent link="base_link"/>
    <child link="UP1_1"/>
  </joint>
  <joint name="Slider 4" type="prismatic">
    <origin xyz="-0.0 0.04 0.015" rpy="0 0 0"/>
    <parent link="UP2_1"/>
    <child link="down1_1"/>
    <axis xyz="1.0 0.0 0.0"/>
    <limit upper="0.12" lower="-0.12" effort="100" velocity="100"/>
  </joint>
  <joint name="Slider 5" type="prismatic">
    <origin xyz="-0.0 -0.08 0.015" rpy="0 0 0"/>
    <parent link="UP1_1"/>
    <child link="down2_1"/>
    <axis xyz="1.0 0.0 0.0"/>
    <limit upper="0.12" lower="-0.12" effort="100" velocity="100"/>
  </joint>
</robot>
